<?xml version="1.0" ?>
<robot name="luna">
   <link name="base_link">
      <inertial>
         <origin xyz="-0.02 0.0 0.0" rpy="-2.964932233208187 -1.5525258585013009 -0.1783493718198772"/>
         <mass value="3.921"/>
         <inertia ixx="0.107027" iyy="0.0980771" izz="0.0244531" ixy="0" ixz="0" iyz="0"/>
      </inertial>
      <visual name="main_body.stl">
         <origin xyz="0.040728233066988084 1.686836337463538e-06 0.006435797901185557" rpy="-0.5784634960683841 -1.5585235363294283 -2.562638887299599"/>
         <geometry>
            <mesh filename="meshes/converted_main_body.stl_abb1c5ff.obj"/>
         </geometry>
      </visual>
   </link>
   <link name="FL_shoulder">
      <inertial>
         <origin xyz="-0.0054 0.00194 -0.000105" rpy="1.5802709600832565 0.0049587370062580405 1.578259940048289"/>
         <mass value="0.678"/>
         <inertia ixx="0.00088403" iyy="0.000596003" izz="0.000479967" ixy="0" ixz="0" iyz="0"/>
      </inertial>
      <visual name="hip_0">
         <origin xyz="-0.01843071034446295 -0.0040328481196227305 -9.402319019014903e-05" rpy="1.5740105370635582 0.00048619432304075616 1.5182896670278467"/>
         <geometry>
            <mesh filename="meshes/converted_hip_0_e6f2f2ff.obj"/>
         </geometry>
      </visual>
      <visual name="hip_1">
         <origin xyz="-0.016345415643551926 0.00997477688846909 -0.0001524228262710644" rpy="1.5722109088073857 -7.145911781369918e-05 1.9406070867887324"/>
         <geometry>
            <mesh filename="meshes/converted_hip_1_abb1c5ff.obj"/>
         </geometry>
      </visual>
   </link>
   <link name="FL_shoulder_joint_jointbody">
      <inertial>
         <origin xyz="0.0 0.0 0.0" rpy="0.0 0.0 0.0"/>
         <mass value="0.001"/>
         <inertia ixx="1e-09" iyy="1e-09" izz="1e-09" ixy="0" ixz="0" iyz="0"/>
      </inertial>
   </link>
   <joint type="revolute" name="FL_shoulder_joint">
      <parent link="base_link"/>
      <child link="FL_shoulder_joint_jointbody"/>
      <origin xyz="0.27 0.1 0.0" rpy="0.0 0.0 0.0"/>
      <axis xyz="-1.0 0.0 0.0"/>
      <limit lower="-1.0472" upper="1.0472" effort="100" velocity="100"/>
   </joint>
   <joint type="fixed" name="FL_shoulder_joint_offset">
      <parent link="FL_shoulder_joint_jointbody"/>
      <child link="FL_shoulder"/>
      <origin xyz="-0.0 -0.0 -0.0" rpy="0.0 0.0 0.0"/>
   </joint>
   <link name="FL_thigh">
      <inertial>
         <origin xyz="-0.00374 -0.0223 -0.0327" rpy="0.1197437565689583 -0.12714340351102904 1.1660365778214339"/>
         <mass value="1.152"/>
         <inertia ixx="0.00594973" iyy="0.00584149" izz="0.000878787" ixy="0" ixz="0" iyz="0"/>
      </inertial>
      <visual name="thigh_0">
         <origin xyz="-0.004160916976041125 -0.016655290134069363 -0.04174767472959812" rpy="0.07764099985956241 -0.12802989905096052 1.4535861164057509"/>
         <geometry>
            <mesh filename="meshes/converted_thigh_0_e6f2f2ff.obj"/>
         </geometry>
      </visual>
      <visual name="thigh_1">
         <origin xyz="-0.005054061099072535 -0.02186542693560587 0.01013743313085582" rpy="-2.113089627253218 -0.7604710691855696 -2.1067941222937856"/>
         <geometry>
            <mesh filename="meshes/converted_thigh_1_abb1c5ff.obj"/>
         </geometry>
      </visual>
   </link>
   <link name="FL_thigh_joint_jointbody">
      <inertial>
         <origin xyz="0.0 0.0 0.0" rpy="0.0 0.0 0.0"/>
         <mass value="0.001"/>
         <inertia ixx="1e-09" iyy="1e-09" izz="1e-09" ixy="0" ixz="0" iyz="0"/>
      </inertial>
   </link>
   <joint type="revolute" name="FL_thigh_joint">
      <parent link="FL_shoulder"/>
      <child link="FL_thigh_joint_jointbody"/>
      <origin xyz="0.0 0.0955 0.0" rpy="0.0 0.0 0.0"/>
      <axis xyz="0.0 -1.0 0.0"/>
      <limit lower="-1.5708" upper="3.4907" effort="100" velocity="100"/>
   </joint>
   <joint type="fixed" name="FL_thigh_joint_offset">
      <parent link="FL_thigh_joint_jointbody"/>
      <child link="FL_thigh"/>
      <origin xyz="-0.0 -0.0 -0.0" rpy="0.0 0.0 0.0"/>
   </joint>
   <link name="FL_calf">
      <inertial>
         <origin xyz="0.00629595 -0.000622121 -0.141417" rpy="-0.004142679594921095 -0.008565579785848376 1.560682489414849"/>
         <mass value="0.241352"/>
         <inertia ixx="0.0014901" iyy="0.00146356" izz="5.31397e-05" ixy="0" ixz="0" iyz="0"/>
      </inertial>
      <visual name="calf_0">
         <origin xyz="0.007579670815585868 -8.678208072411072e-05 -0.12646263355676604" rpy="-0.040522351426425574 -0.001996311907713544 1.5880136349124139"/>
         <geometry>
            <mesh filename="meshes/converted_calf_0_abb1c5ff.obj"/>
         </geometry>
      </visual>
      <visual name="calf_1">
         <origin xyz="-0.00553202586848318 0.0002013131343986809 -0.21845058088589975" rpy="3.141592653589793 -1.0095239929349717 0.0"/>
         <geometry>
            <mesh filename="meshes/converted_calf_1_000000ff.obj"/>
         </geometry>
      </visual>
      <visual name="foot">
         <origin xyz="-0.005646883009570938 2.7875429472840093e-05 -0.21846976266512524" rpy="3.141592653589793 -1.009081437773671 0.0"/>
         <geometry>
            <mesh filename="meshes/converted_foot_000000ff.obj"/>
         </geometry>
      </visual>
   </link>
   <link name="FL_calf_joint_jointbody">
      <inertial>
         <origin xyz="0.0 0.0 0.0" rpy="0.0 0.0 0.0"/>
         <mass value="0.001"/>
         <inertia ixx="1e-09" iyy="1e-09" izz="1e-09" ixy="0" ixz="0" iyz="0"/>
      </inertial>
   </link>
   <joint type="revolute" name="FL_calf_joint">
      <parent link="FL_thigh"/>
      <child link="FL_calf_joint_jointbody"/>
      <origin xyz="0.0 0.0 -0.213" rpy="0.0 0.0 0.0"/>
      <axis xyz="0.0 1.0 0.0"/>
      <limit lower="-2.7227" upper="-0.83776" effort="100" velocity="100"/>
   </joint>
   <joint type="fixed" name="FL_calf_joint_offset">
      <parent link="FL_calf_joint_jointbody"/>
      <child link="FL_calf"/>
      <origin xyz="-0.0 -0.0 -0.0" rpy="0.0 0.0 0.0"/>
   </joint>
   <link name="FR_shoulder">
      <inertial>
         <origin xyz="-0.0054 -0.00194 -0.000105" rpy="1.5802709600832567 -0.0049587370062580405 1.5633327135415043"/>
         <mass value="0.678"/>
         <inertia ixx="0.00088403" iyy="0.000596003" izz="0.000479967" ixy="0" ixz="0" iyz="0"/>
      </inertial>
      <visual name="hip_0">
         <origin xyz="-0.018430710344462954 0.004032856813899393 9.364953189083477e-05" rpy="-1.5675869792230035 -0.0005787202316687168 -1.5182896644386685"/>
         <geometry>
            <mesh filename="meshes/converted_hip_0_e6f2f2ff.obj"/>
         </geometry>
      </visual>
      <visual name="hip_1">
         <origin xyz="-0.01634541564355193 -0.009974762723130364 0.0001533470246027431" rpy="-1.5693482561586933 -1.4930706031313079e-05 -1.9406070858422027"/>
         <geometry>
            <mesh filename="meshes/converted_hip_1_abb1c5ff.obj"/>
         </geometry>
      </visual>
   </link>
   <link name="FR_shoulder_joint_jointbody">
      <inertial>
         <origin xyz="0.0 0.0 0.0" rpy="0.0 0.0 0.0"/>
         <mass value="0.001"/>
         <inertia ixx="1e-09" iyy="1e-09" izz="1e-09" ixy="0" ixz="0" iyz="0"/>
      </inertial>
   </link>
   <joint type="revolute" name="FR_shoulder_joint">
      <parent link="base_link"/>
      <child link="FR_shoulder_joint_jointbody"/>
      <origin xyz="0.27 -0.1 0.0" rpy="0.0 0.0 0.0"/>
      <axis xyz="-1.0 0.0 0.0"/>
      <limit lower="-1.0472" upper="1.0472" effort="100" velocity="100"/>
   </joint>
   <joint type="fixed" name="FR_shoulder_joint_offset">
      <parent link="FR_shoulder_joint_jointbody"/>
      <child link="FR_shoulder"/>
      <origin xyz="-0.0 -0.0 -0.0" rpy="0.0 0.0 0.0"/>
   </joint>
   <link name="FR_thigh">
      <inertial>
         <origin xyz="-0.00374 0.0223 -0.0327" rpy="0.11974375656895819 0.12714340351102926 1.9755560757683592"/>
         <mass value="1.152"/>
         <inertia ixx="0.00594973" iyy="0.00584149" izz="0.000878787" ixy="0" ixz="0" iyz="0"/>
      </inertial>
      <visual name="thigh_mirror_0">
         <origin xyz="-0.0041609164060553705 0.01665529126767645 -0.041747646910983684" rpy="0.07764122929299322 0.12802995713367582 1.6880063746100311"/>
         <geometry>
            <mesh filename="meshes/converted_thigh_mirror_0_e6f2f2ff.obj"/>
         </geometry>
      </visual>
      <visual name="thigh_mirror_1">
         <origin xyz="-0.005054066936956911 0.021865454389318445 0.010137527299568839" rpy="-1.0285328532149474 -0.7604730657794242 2.1068035867353703"/>
         <geometry>
            <mesh filename="meshes/converted_thigh_mirror_1_abb1c5ff.obj"/>
         </geometry>
      </visual>
   </link>
   <link name="FR_thigh_joint_jointbody">
      <inertial>
         <origin xyz="0.0 0.0 0.0" rpy="0.0 0.0 0.0"/>
         <mass value="0.001"/>
         <inertia ixx="1e-09" iyy="1e-09" izz="1e-09" ixy="0" ixz="0" iyz="0"/>
      </inertial>
   </link>
   <joint type="revolute" name="FR_thigh_joint">
      <parent link="FR_shoulder"/>
      <child link="FR_thigh_joint_jointbody"/>
      <origin xyz="0.0 -0.0955 0.0" rpy="0.0 0.0 0.0"/>
      <axis xyz="0.0 1.0 0.0"/>
      <limit lower="-3.4907" upper="1.5708" effort="100" velocity="100"/>
   </joint>
   <joint type="fixed" name="FR_thigh_joint_offset">
      <parent link="FR_thigh_joint_jointbody"/>
      <child link="FR_thigh"/>
      <origin xyz="-0.0 -0.0 -0.0" rpy="0.0 0.0 0.0"/>
   </joint>
   <link name="FR_calf">
      <inertial>
         <origin xyz="0.00629595 0.000622121 -0.141417" rpy="-0.004142679594921206 0.008565579785848376 1.5809101641749441"/>
         <mass value="0.241352"/>
         <inertia ixx="0.0014901" iyy="0.00146356" izz="5.31397e-05" ixy="0" ixz="0" iyz="0"/>
      </inertial>
      <visual name="calf_mirror_0">
         <origin xyz="0.007579674906078829 8.678091749779236e-05 -0.1264626356142243" rpy="-0.04052236637026685 0.0019963181221138715 1.553578911231777"/>
         <geometry>
            <mesh filename="meshes/converted_calf_mirror_0_abb1c5ff.obj"/>
         </geometry>
      </visual>
      <visual name="calf_mirror_1">
         <origin xyz="-0.0055320126054020195 -0.0002013129577844697 -0.21845058391647268" rpy="3.141592653589793 -1.009524480350323 0.0"/>
         <geometry>
            <mesh filename="meshes/converted_calf_mirror_1_000000ff.obj"/>
         </geometry>
      </visual>
      <visual name="foot">
         <origin xyz="-0.005646883009570938 2.7875429472840093e-05 -0.21846976266512524" rpy="3.141592653589793 -1.009081437773671 0.0"/>
         <geometry>
            <mesh filename="meshes/converted_foot_000000ff.obj"/>
         </geometry>
      </visual>
   </link>
   <link name="FR_calf_joint_jointbody">
      <inertial>
         <origin xyz="0.0 0.0 0.0" rpy="0.0 0.0 0.0"/>
         <mass value="0.001"/>
         <inertia ixx="1e-09" iyy="1e-09" izz="1e-09" ixy="0" ixz="0" iyz="0"/>
      </inertial>
   </link>
   <joint type="revolute" name="FR_calf_joint">
      <parent link="FR_thigh"/>
      <child link="FR_calf_joint_jointbody"/>
      <origin xyz="0.0 0.0 -0.213" rpy="0.0 0.0 0.0"/>
      <axis xyz="0.0 -1.0 0.0"/>
      <limit lower="0.83776" upper="2.7227" effort="100" velocity="100"/>
   </joint>
   <joint type="fixed" name="FR_calf_joint_offset">
      <parent link="FR_calf_joint_jointbody"/>
      <child link="FR_calf"/>
      <origin xyz="-0.0 -0.0 -0.0" rpy="0.0 0.0 0.0"/>
   </joint>
   <link name="BL_shoulder">
      <inertial>
         <origin xyz="0.0054 0.00194 -0.000105" rpy="1.5613216935065368 0.0049587370062580405 1.5633327135415043"/>
         <mass value="0.678"/>
         <inertia ixx="0.00088403" iyy="0.000596003" izz="0.000479967" ixy="0" ixz="0" iyz="0"/>
      </inertial>
      <visual name="hip_0">
         <origin xyz="0.018430701553764958 -0.004032848119622731 9.573086144687589e-05" rpy="-1.5676746424455874 -0.00048133162500496596 1.6233030313225587"/>
         <geometry>
            <mesh filename="meshes/converted_hip_0_e6f2f2ff.obj"/>
         </geometry>
      </visual>
      <visual name="hip_1">
         <origin xyz="0.016345401450868224 0.009974776888469091 0.00015393728721643424" rpy="-1.5694681346062742 3.797049383669204e-05 1.2009855620742587"/>
         <geometry>
            <mesh filename="meshes/converted_hip_1_abb1c5ff.obj"/>
         </geometry>
      </visual>
   </link>
   <link name="BL_shoulder_joint_jointbody">
      <inertial>
         <origin xyz="0.0 0.0 0.0" rpy="0.0 0.0 0.0"/>
         <mass value="0.001"/>
         <inertia ixx="1e-09" iyy="1e-09" izz="1e-09" ixy="0" ixz="0" iyz="0"/>
      </inertial>
   </link>
   <joint type="revolute" name="BL_shoulder_joint">
      <parent link="base_link"/>
      <child link="BL_shoulder_joint_jointbody"/>
      <origin xyz="-0.27 0.0665 0.0" rpy="0.0 0.0 0.0"/>
      <axis xyz="1.0 0.0 0.0"/>
      <limit lower="-1.0472" upper="1.0472" effort="100" velocity="100"/>
   </joint>
   <joint type="fixed" name="BL_shoulder_joint_offset">
      <parent link="BL_shoulder_joint_jointbody"/>
      <child link="BL_shoulder"/>
      <origin xyz="-0.0 -0.0 -0.0" rpy="0.0 0.0 0.0"/>
   </joint>
   <link name="BL_thigh">
      <inertial>
         <origin xyz="-0.00374 -0.0223 -0.0327" rpy="0.1197437565689583 -0.12714340351102904 1.1660365778214339"/>
         <mass value="1.152"/>
         <inertia ixx="0.00594973" iyy="0.00584149" izz="0.000878787" ixy="0" ixz="0" iyz="0"/>
      </inertial>
      <visual name="thigh_0">
         <origin xyz="-0.004160916976041125 -0.016655290134069363 -0.04174767472959812" rpy="0.07764099985956241 -0.12802989905096052 1.4535861164057509"/>
         <geometry>
            <mesh filename="meshes/converted_thigh_0_e6f2f2ff.obj"/>
         </geometry>
      </visual>
      <visual name="thigh_1">
         <origin xyz="-0.005054061099072535 -0.02186542693560587 0.01013743313085582" rpy="-2.113089627253218 -0.7604710691855696 -2.1067941222937856"/>
         <geometry>
            <mesh filename="meshes/converted_thigh_1_abb1c5ff.obj"/>
         </geometry>
      </visual>
   </link>
   <link name="BL_thigh_joint_jointbody">
      <inertial>
         <origin xyz="0.0 0.0 0.0" rpy="0.0 0.0 0.0"/>
         <mass value="0.001"/>
         <inertia ixx="1e-09" iyy="1e-09" izz="1e-09" ixy="0" ixz="0" iyz="0"/>
      </inertial>
   </link>
   <joint type="revolute" name="BL_thigh_joint">
      <parent link="BL_shoulder"/>
      <child link="BL_thigh_joint_jointbody"/>
      <origin xyz="0.0 0.0955 0.0" rpy="0.0 0.0 0.0"/>
      <axis xyz="0.0 -1.0 0.0"/>
      <limit lower="-1.5708" upper="3.4907" effort="100" velocity="100"/>
   </joint>
   <joint type="fixed" name="BL_thigh_joint_offset">
      <parent link="BL_thigh_joint_jointbody"/>
      <child link="BL_thigh"/>
      <origin xyz="-0.0 -0.0 -0.0" rpy="0.0 0.0 0.0"/>
   </joint>
   <link name="BL_calf">
      <inertial>
         <origin xyz="0.00629595 -0.000622121 -0.141417" rpy="-0.004142679594921095 -0.008565579785848376 1.560682489414849"/>
         <mass value="0.241352"/>
         <inertia ixx="0.0014901" iyy="0.00146356" izz="5.31397e-05" ixy="0" ixz="0" iyz="0"/>
      </inertial>
      <visual name="calf_0">
         <origin xyz="0.007579670815585868 -8.678208072411072e-05 -0.12646263355676604" rpy="-0.040522351426425574 -0.001996311907713544 1.5880136349124139"/>
         <geometry>
            <mesh filename="meshes/converted_calf_0_abb1c5ff.obj"/>
         </geometry>
      </visual>
      <visual name="calf_1">
         <origin xyz="-0.00553202586848318 0.0002013131343986809 -0.21845058088589975" rpy="3.141592653589793 -1.0095239929349717 0.0"/>
         <geometry>
            <mesh filename="meshes/converted_calf_1_000000ff.obj"/>
         </geometry>
      </visual>
      <visual name="foot">
         <origin xyz="-0.005646883009570938 2.7875429472840093e-05 -0.21846976266512524" rpy="3.141592653589793 -1.009081437773671 0.0"/>
         <geometry>
            <mesh filename="meshes/converted_foot_000000ff.obj"/>
         </geometry>
      </visual>
   </link>
   <link name="BL_calf_joint_jointbody">
      <inertial>
         <origin xyz="0.0 0.0 0.0" rpy="0.0 0.0 0.0"/>
         <mass value="0.001"/>
         <inertia ixx="1e-09" iyy="1e-09" izz="1e-09" ixy="0" ixz="0" iyz="0"/>
      </inertial>
   </link>
   <joint type="revolute" name="BL_calf_joint">
      <parent link="BL_thigh"/>
      <child link="BL_calf_joint_jointbody"/>
      <origin xyz="0.0 0.0 -0.213" rpy="0.0 0.0 0.0"/>
      <axis xyz="0.0 1.0 0.0"/>
      <limit lower="-2.7227" upper="-0.83776" effort="100" velocity="100"/>
   </joint>
   <joint type="fixed" name="BL_calf_joint_offset">
      <parent link="BL_calf_joint_jointbody"/>
      <child link="BL_calf"/>
      <origin xyz="-0.0 -0.0 -0.0" rpy="0.0 0.0 0.0"/>
   </joint>
   <link name="BR_shoulder">
      <inertial>
         <origin xyz="0.0054 -0.00194 -0.000105" rpy="1.5613216935065366 -0.0049587370062580405 1.578259940048289"/>
         <mass value="0.678"/>
         <inertia ixx="0.00088403" iyy="0.000596003" izz="0.000479967" ixy="0" ixz="0" iyz="0"/>
      </inertial>
      <visual name="hip_0">
         <origin xyz="0.018430718942318257 0.0040328568138993034 -9.19418598285519e-05" rpy="1.5740982002911668 0.0005835829253857394 -1.6233029353795454"/>
         <geometry>
            <mesh filename="meshes/converted_hip_0_e6f2f2ff.obj"/>
         </geometry>
      </visual>
      <visual name="hip_1">
         <origin xyz="0.016345429781545566 -0.00997476272313044 -0.00015183256234490365" rpy="1.5723307872549515 -1.8557917652817224e-05 -1.2009855679042722"/>
         <geometry>
            <mesh filename="meshes/converted_hip_1_abb1c5ff.obj"/>
         </geometry>
      </visual>
   </link>
   <link name="BR_shoulder_joint_jointbody">
      <inertial>
         <origin xyz="0.0 0.0 0.0" rpy="0.0 0.0 0.0"/>
         <mass value="0.001"/>
         <inertia ixx="1e-09" iyy="1e-09" izz="1e-09" ixy="0" ixz="0" iyz="0"/>
      </inertial>
   </link>
   <joint type="revolute" name="BR_shoulder_joint">
      <parent link="base_link"/>
      <child link="BR_shoulder_joint_jointbody"/>
      <origin xyz="-0.27 -0.0665 0.0" rpy="0.0 0.0 0.0"/>
      <axis xyz="-1.0 0.0 0.0"/>
      <limit lower="-1.0472" upper="1.0472" effort="100" velocity="100"/>
   </joint>
   <joint type="fixed" name="BR_shoulder_joint_offset">
      <parent link="BR_shoulder_joint_jointbody"/>
      <child link="BR_shoulder"/>
      <origin xyz="-0.0 -0.0 -0.0" rpy="0.0 0.0 0.0"/>
   </joint>
   <link name="BR_thigh">
      <inertial>
         <origin xyz="-0.00374 0.0223 -0.0327" rpy="0.11974375656895819 0.12714340351102926 1.9755560757683592"/>
         <mass value="1.152"/>
         <inertia ixx="0.00594973" iyy="0.00584149" izz="0.000878787" ixy="0" ixz="0" iyz="0"/>
      </inertial>
      <visual name="thigh_mirror_0">
         <origin xyz="-0.0041609164060553705 0.01665529126767645 -0.041747646910983684" rpy="0.07764122929299322 0.12802995713367582 1.6880063746100311"/>
         <geometry>
            <mesh filename="meshes/converted_thigh_mirror_0_e6f2f2ff.obj"/>
         </geometry>
      </visual>
      <visual name="thigh_mirror_1">
         <origin xyz="-0.005054066936956911 0.021865454389318445 0.010137527299568839" rpy="-1.0285328532149474 -0.7604730657794242 2.1068035867353703"/>
         <geometry>
            <mesh filename="meshes/converted_thigh_mirror_1_abb1c5ff.obj"/>
         </geometry>
      </visual>
   </link>
   <link name="BR_thigh_joint_jointbody">
      <inertial>
         <origin xyz="0.0 0.0 0.0" rpy="0.0 0.0 0.0"/>
         <mass value="0.001"/>
         <inertia ixx="1e-09" iyy="1e-09" izz="1e-09" ixy="0" ixz="0" iyz="0"/>
      </inertial>
   </link>
   <joint type="revolute" name="BR_thigh_joint">
      <parent link="BR_shoulder"/>
      <child link="BR_thigh_joint_jointbody"/>
      <origin xyz="0.0 -0.0955 0.0" rpy="0.0 0.0 0.0"/>
      <axis xyz="0.0 1.0 0.0"/>
      <limit lower="-3.4907" upper="1.5708" effort="100" velocity="100"/>
   </joint>
   <joint type="fixed" name="BR_thigh_joint_offset">
      <parent link="BR_thigh_joint_jointbody"/>
      <child link="BR_thigh"/>
      <origin xyz="-0.0 -0.0 -0.0" rpy="0.0 0.0 0.0"/>
   </joint>
   <link name="BR_calf">
      <inertial>
         <origin xyz="0.00629595 0.000622121 -0.141417" rpy="-0.004142679594921206 0.008565579785848376 1.5809101641749441"/>
         <mass value="0.241352"/>
         <inertia ixx="0.0014901" iyy="0.00146356" izz="5.31397e-05" ixy="0" ixz="0" iyz="0"/>
      </inertial>
      <visual name="calf_mirror_0">
         <origin xyz="0.007579674906078829 8.678091749779236e-05 -0.1264626356142243" rpy="-0.04052236637026685 0.0019963181221138715 1.553578911231777"/>
         <geometry>
            <mesh filename="meshes/converted_calf_mirror_0_abb1c5ff.obj"/>
         </geometry>
      </visual>
      <visual name="calf_mirror_1">
         <origin xyz="-0.0055320126054020195 -0.0002013129577844697 -0.21845058391647268" rpy="3.141592653589793 -1.009524480350323 0.0"/>
         <geometry>
            <mesh filename="meshes/converted_calf_mirror_1_000000ff.obj"/>
         </geometry>
      </visual>
      <visual name="foot">
         <origin xyz="-0.005646883009570938 2.7875429472840093e-05 -0.21846976266512524" rpy="3.141592653589793 -1.009081437773671 0.0"/>
         <geometry>
            <mesh filename="meshes/converted_foot_000000ff.obj"/>
         </geometry>
      </visual>
   </link>
   <link name="BR_calf_joint_jointbody">
      <inertial>
         <origin xyz="0.0 0.0 0.0" rpy="0.0 0.0 0.0"/>
         <mass value="0.001"/>
         <inertia ixx="1e-09" iyy="1e-09" izz="1e-09" ixy="0" ixz="0" iyz="0"/>
      </inertial>
   </link>
   <joint type="revolute" name="BR_calf_joint">
      <parent link="BR_thigh"/>
      <child link="BR_calf_joint_jointbody"/>
      <origin xyz="0.0 0.0 -0.213" rpy="0.0 0.0 0.0"/>
      <axis xyz="0.0 -1.0 0.0"/>
      <limit lower="0.83776" upper="2.7227" effort="100" velocity="100"/>
   </joint>
   <joint type="fixed" name="BR_calf_joint_offset">
      <parent link="BR_calf_joint_jointbody"/>
      <child link="BR_calf"/>
      <origin xyz="-0.0 -0.0 -0.0" rpy="0.0 0.0 0.0"/>
   </joint>
</robot>
