<mujoco model="Robot">
  <option iterations="50" timestep="0.001" solver="PGS" gravity="0 0 -9.81" />

  <compiler angle="radian" meshdir="meshes" eulerseq="zyx" autolimits="true" />

  <default>
    <joint limited="true" damping="0.01" armature="0.01" frictionloss="0.01" />
    <geom condim="4" contype="1" conaffinity="15" friction="0.9 0.2 0.2" solref="0.001 2" />
    <motor ctrllimited="true" />
    <equality solref="0.001 2" />
    <default class="visualgeom">
      <geom material="visualgeom" condim="1" contype="0" conaffinity="0" />
    </default>
  </default>

  <worldbody>
    <light directional="true" diffuse="0.4 0.4 0.4" specular="0.1 0.1 0.1" pos="0 0 5.0" dir="0 0 -1" castshadow="false" />
    <light directional="true" diffuse="0.6 0.6 0.6" specular="0.2 0.2 0.2" pos="0 0 4" dir="0 0 -1" />
    <camera name="fixed" pos="0 -3.0 0.8816250237158589" xyaxes="1 0 0 0 0 1" />
    <camera name="track" mode="trackcom" pos="0 -3.0 0.8816250237158589" xyaxes="1 0 0 0 0 1" />
    <body name="root" pos="0 0 0.3816250237158589" quat="1 0 0 0">
      <freejoint name="root" />
      <inertial pos="0 0 0" mass="10.0" fullinertia="0.158460467 0.468645637 0.524474661 0.0001216600 -0.0155444692 -0.0000312000" />
      <site name="imu" size="0.01" pos="0 0 0" />
      <body name="FL_shoulder" pos="0.142 -0.17 0.018" quat="0.707107 0.707107 0 0">
        <inertial pos="0.0239541 1.32614e-05 0.0573496" quat="0.497342 0.501472 0.49851 0.502658" mass="0.296069" diaginertia="0.00042352 0.000361861 0.000206498" />
        <joint name="FL_shoulder_joint" pos="0 0 0" axis="0 0 -1" range="-3.14159 3.14159" actuatorfrcrange="-12 12" />
        <body name="FL_LUNA_UPPER_LEG_ASM" pos="0.04 0 0.05" quat="0.5 -0.5 0.5 0.5">
          <inertial pos="-0.00450381 -0.0553839 -0.0303577" quat="0.688279 0.233616 -0.097768 0.679806" mass="0.541351" diaginertia="0.00145754 0.0010471 0.000510163" />
          <joint name="FL_upper_leg_joint" pos="0 0 0" axis="0 1 0" range="-3.14159 3.14159" actuatorfrcrange="-12 12" />
          <geom size="0.12766 0.028 0.05039" pos="-0.000736336 -0.0309636 -0.07227" quat="0.707107 0 -0.707107 0" type="box" contype="1" conaffinity="0" density="0" group="1" class="visualgeom" />
          <geom type="box" rgba="" size="0.12766 0.028 0.05039" pos="-0.000736336 -0.0309636 -0.07227" quat="0.707107 0 -0.707107 0" />
          <body name="FL_lower_leg" pos="0.02 0 -0.2" quat="-1.4503e-10 0.707107 0.707107 -1.4503e-10">
            <inertial pos="0.005 0 -0.0781594" mass="0.0801993" diaginertia="0.000298784 0.000292799 7.32197e-06" />
            <joint name="FL_lower_leg_joint" pos="0 0 0" axis="1 0 0" range="-3.14159 3.14159" actuatorfrcrange="-12 12" />
            <geom size="0.005 0.019937 0.0796591" pos="0.005 0 0.119966" type="box" contype="1" conaffinity="0" density="0" group="1" class="visualgeom" />
            <geom name="FL_lower_leg" type="box" rgba="" size="0.005 0.019937 0.0796591" pos="0.005 0 0.119966" />
          </body>
        </body>
      </body>
      <body name="BL_shoulder" pos="0.115 0.35 0.018" quat="0.707107 0.707107 0 0">
        <inertial pos="0.0239541 1.32614e-05 0.0573496" quat="0.497342 0.501472 0.49851 0.502658" mass="0.296069" diaginertia="0.00042352 0.000361861 0.000206498" />
        <joint name="BL_shoulder_joint" pos="0 0 0" axis="0 0 1" range="-3.14159 3.14159" actuatorfrcrange="-12 12" />
        <body name="BL_LUNA_UPPER_LEG_ASM" pos="0.04 0 0.05" quat="0.5 -0.5 0.5 0.5">
          <inertial pos="-0.00450381 -0.0553839 -0.0303577" quat="0.688279 0.233616 -0.097768 0.679806" mass="0.541351" diaginertia="0.00145754 0.0010471 0.000510163" />
          <joint name="BL_upper_leg_joint" pos="0 0 0" axis="0 1 0" range="-3.14159 3.14159" actuatorfrcrange="-12 12" />
          <geom size="0.12766 0.028 0.05039" pos="-0.000736336 -0.0309636 -0.07227" quat="0.707107 0 -0.707107 0" type="box" contype="1" conaffinity="0" density="0" group="1" class="visualgeom" />
          <geom type="box" rgba="" size="0.12766 0.028 0.05039" pos="-0.000736336 -0.0309636 -0.07227" quat="0.707107 0 -0.707107 0" />
          <body name="BL_lower_leg" pos="0.02 0 -0.2" quat="-1.4503e-10 0.707107 0.707107 -1.4503e-10">
            <inertial pos="0.005 0 -0.0781594" mass="0.0801993" diaginertia="0.000298784 0.000292799 7.32197e-06" />
            <joint name="BL_lower_leg_joint" pos="0 0 0" axis="1 0 0" range="-3.14159 3.14159" actuatorfrcrange="-12 12" />
            <geom name="BL_lower_leg" size="0.005 0.019937 0.0796591" pos="0.005 0 0.119966" type="box" contype="1" conaffinity="0" density="0" group="1" class="visualgeom" />
            <geom type="box" rgba="" size="0.005 0.019937 0.0796591" pos="0.005 0 0.119966" />
          </body>
        </body>
      </body>
      <body name="FR_shoulder" pos="-0.142 -0.17 0.018" quat="-1.4503e-10 -1.4503e-10 -0.707107 0.707107">
        <inertial pos="0.0239541 1.32614e-05 0.0573496" quat="0.497342 0.501472 0.49851 0.502658" mass="0.296069" diaginertia="0.00042352 0.000361861 0.000206498" />
        <joint name="FR_shoulder_joint" pos="0 0 0" axis="0 0 -1" range="-3.14159 3.14159" actuatorfrcrange="-12 12" />
        <body name="FR_LUNA_UPPER_LEG_ASM" pos="0.04 0 0.05" quat="0.5 0.5 -0.5 0.5">
          <inertial pos="-0.00450381 -0.0553839 -0.0303577" quat="0.688279 0.233616 -0.097768 0.679806" mass="0.541351" diaginertia="0.00145754 0.0010471 0.000510163" />
          <joint name="FR_upper_leg_joint" pos="0 0 0" axis="0 -1 0" range="-3.14159 3.14159" actuatorfrcrange="-12 12" />
          <geom size="0.12766 0.028 0.05039" pos="-0.000736336 -0.0309636 -0.07227" quat="0.707107 0 -0.707107 0" type="box" contype="1" conaffinity="0" density="0" group="1" class="visualgeom" />
          <geom type="box" rgba="" size="0.12766 0.028 0.05039" pos="-0.000736336 -0.0309636 -0.07227" quat="0.707107 0 -0.707107 0" />
          <body name="FR_lower_leg" pos="-0.02 0 -0.2" quat="0.707107 0 0 0.707107">
            <inertial pos="0.005 0 -0.0781594" mass="0.0801993" diaginertia="0.000298784 0.000292799 7.32197e-06" />
            <joint name="FR_lower_leg_joint" pos="0 0 0" axis="-1 0 0" range="-3.14159 3.14159" actuatorfrcrange="-12 12" />
            <geom name="FR_lower_leg" size="0.005 0.019937 0.0796591" pos="0.005 0 -0.119966" type="box" contype="1" conaffinity="0" density="0" group="1" class="visualgeom" />
            <geom type="box" rgba="" size="0.005 0.019937 0.0796591" pos="0.005 0 -0.119966" />
          </body>
        </body>
      </body>
      <body name="BR_shoulder" pos="-0.115 0.35 0.018" quat="-1.4503e-10 -1.4503e-10 -0.707107 0.707107">
        <inertial pos="0.0239541 1.32614e-05 0.0573496" quat="0.497342 0.501472 0.49851 0.502658" mass="0.296069" diaginertia="0.00042352 0.000361861 0.000206498" />
        <joint name="BR_shoulder_joint" pos="0 0 0" axis="0 0 1" range="-3.14159 3.14159" actuatorfrcrange="-12 12" />
        <body name="BR_LUNA_UPPER_LEG_ASM" pos="0.04 0 0.05" quat="0.5 0.5 -0.5 0.5">
          <inertial pos="-0.00450381 -0.0553839 -0.0303577" quat="0.688279 0.233616 -0.097768 0.679806" mass="0.541351" diaginertia="0.00145754 0.0010471 0.000510163" />
          <joint name="BR_upper_leg_joint" pos="0 0 0" axis="0 -1 0" range="-3.14159 3.14159" actuatorfrcrange="-12 12" />
          <geom size="0.12766 0.028 0.05039" pos="-0.000736336 -0.0309636 -0.07227" quat="0.707107 0 -0.707107 0" type="box" contype="1" conaffinity="0" density="0" group="1" class="visualgeom" />
          <geom type="box" rgba="" size="0.12766 0.028 0.05039" pos="-0.000736336 -0.0309636 -0.07227" quat="0.707107 0 -0.707107 0" />
          <body name="BR_lower_leg" pos="-0.02 0 -0.2" quat="0.707107 0 0 0.707107">
            <inertial pos="0.005 0 -0.0781594" mass="0.0801993" diaginertia="0.000298784 0.000292799 7.32197e-06" />
            <joint name="BR_lower_leg_joint" pos="0 0 0" axis="-1 0 0" range="-3.14159 3.14159" actuatorfrcrange="-12 12" />
            <geom name="BR_lower_leg" size="0.005 0.019937 0.0796591" pos="0.005 0 -0.119966" type="box" contype="1" conaffinity="0" density="0" group="1" class="visualgeom" />
            <geom type="box" rgba="" size="0.005 0.019937 0.0796591" pos="0.005 0 -0.119966" />
          </body>
        </body>
      </body>
    </body>
  </worldbody>

  <asset>
    <texture name="texplane" type="2d" builtin="checker" rgb1=".0 .0 .0" rgb2=".8 .8 .8" width="100" height="100" />
    <material name="matplane" reflectance="0." texture="texplane" texrepeat="1 1" texuniform="true" />
    <material name="visualgeom" rgba="0.5 0.9 0.2 1" />
  </asset>

  <actuator>
    <motor name="FL_shoulder_joint" joint="FL_shoulder_joint" ctrllimited="true" ctrlrange="-12 12" gear="1" />
    <motor name="FL_upper_leg_joint" joint="FL_upper_leg_joint" ctrllimited="true" ctrlrange="-12 12" gear="1" />
    <motor name="FL_lower_leg_joint" joint="FL_lower_leg_joint" ctrllimited="true" ctrlrange="-12 12" gear="1" />
    <motor name="BL_shoulder_joint" joint="BL_shoulder_joint" ctrllimited="true" ctrlrange="-12 12" gear="1" />
    <motor name="BL_upper_leg_joint" joint="BL_upper_leg_joint" ctrllimited="true" ctrlrange="-12 12" gear="1" />
    <motor name="BL_lower_leg_joint" joint="BL_lower_leg_joint" ctrllimited="true" ctrlrange="-12 12" gear="1" />
    <motor name="FR_shoulder_joint" joint="FR_shoulder_joint" ctrllimited="true" ctrlrange="-12 12" gear="1" />
    <motor name="FR_upper_leg_joint" joint="FR_upper_leg_joint" ctrllimited="true" ctrlrange="-12 12" gear="1" />
    <motor name="FR_lower_leg_joint" joint="FR_lower_leg_joint" ctrllimited="true" ctrlrange="-12 12" gear="1" />
    <motor name="BR_shoulder_joint" joint="BR_shoulder_joint" ctrllimited="true" ctrlrange="-12 12" gear="1" />
    <motor name="BR_upper_leg_joint" joint="BR_upper_leg_joint" ctrllimited="true" ctrlrange="-12 12" gear="1" />
    <motor name="BR_lower_leg_joint" joint="BR_lower_leg_joint" ctrllimited="true" ctrlrange="-12 12" gear="1" />
  </actuator>

  <sensor>
    <actuatorpos name="FL_shoulder_joint_p" actuator="FL_shoulder_joint" />
    <actuatorvel name="FL_shoulder_joint_v" actuator="FL_shoulder_joint" />
    <actuatorfrc name="FL_shoulder_joint_f" actuator="FL_shoulder_joint" noise="0.001" />
    <actuatorpos name="FL_upper_leg_joint_p" actuator="FL_upper_leg_joint" />
    <actuatorvel name="FL_upper_leg_joint_v" actuator="FL_upper_leg_joint" />
    <actuatorfrc name="FL_upper_leg_joint_f" actuator="FL_upper_leg_joint" noise="0.001" />
    <actuatorpos name="FL_lower_leg_joint_p" actuator="FL_lower_leg_joint" />
    <actuatorvel name="FL_lower_leg_joint_v" actuator="FL_lower_leg_joint" />
    <actuatorfrc name="FL_lower_leg_joint_f" actuator="FL_lower_leg_joint" noise="0.001" />
    <actuatorpos name="BL_shoulder_joint_p" actuator="BL_shoulder_joint" />
    <actuatorvel name="BL_shoulder_joint_v" actuator="BL_shoulder_joint" />
    <actuatorfrc name="BL_shoulder_joint_f" actuator="BL_shoulder_joint" noise="0.001" />
    <actuatorpos name="BL_upper_leg_joint_p" actuator="BL_upper_leg_joint" />
    <actuatorvel name="BL_upper_leg_joint_v" actuator="BL_upper_leg_joint" />
    <actuatorfrc name="BL_upper_leg_joint_f" actuator="BL_upper_leg_joint" noise="0.001" />
    <actuatorpos name="BL_lower_leg_joint_p" actuator="BL_lower_leg_joint" />
    <actuatorvel name="BL_lower_leg_joint_v" actuator="BL_lower_leg_joint" />
    <actuatorfrc name="BL_lower_leg_joint_f" actuator="BL_lower_leg_joint" noise="0.001" />
    <actuatorpos name="FR_shoulder_joint_p" actuator="FR_shoulder_joint" />
    <actuatorvel name="FR_shoulder_joint_v" actuator="FR_shoulder_joint" />
    <actuatorfrc name="FR_shoulder_joint_f" actuator="FR_shoulder_joint" noise="0.001" />
    <actuatorpos name="FR_upper_leg_joint_p" actuator="FR_upper_leg_joint" />
    <actuatorvel name="FR_upper_leg_joint_v" actuator="FR_upper_leg_joint" />
    <actuatorfrc name="FR_upper_leg_joint_f" actuator="FR_upper_leg_joint" noise="0.001" />
    <actuatorpos name="FR_lower_leg_joint_p" actuator="FR_lower_leg_joint" />
    <actuatorvel name="FR_lower_leg_joint_v" actuator="FR_lower_leg_joint" />
    <actuatorfrc name="FR_lower_leg_joint_f" actuator="FR_lower_leg_joint" noise="0.001" />
    <actuatorpos name="BR_shoulder_joint_p" actuator="BR_shoulder_joint" />
    <actuatorvel name="BR_shoulder_joint_v" actuator="BR_shoulder_joint" />
    <actuatorfrc name="BR_shoulder_joint_f" actuator="BR_shoulder_joint" noise="0.001" />
    <actuatorpos name="BR_upper_leg_joint_p" actuator="BR_upper_leg_joint" />
    <actuatorvel name="BR_upper_leg_joint_v" actuator="BR_upper_leg_joint" />
    <actuatorfrc name="BR_upper_leg_joint_f" actuator="BR_upper_leg_joint" noise="0.001" />
    <actuatorpos name="BR_lower_leg_joint_p" actuator="BR_lower_leg_joint" />
    <actuatorvel name="BR_lower_leg_joint_v" actuator="BR_lower_leg_joint" />
    <actuatorfrc name="BR_lower_leg_joint_f" actuator="BR_lower_leg_joint" noise="0.001" />
    <framequat name="orientation" objtype="site" noise="0.001" objname="imu" />
    <gyro name="angular-velocity" site="imu" noise="0.005" cutoff="34.9" />
  </sensor>

  <keyframe>
    <!--Generalized coordinates: 6 free flyer for luna and 12 internal-->
    <key name="home" qpos="0 0 0 0 0 0 0 0 -0.4 0.8 0 -0.4 0.8 0 -0.4 0.8 0 -0.4 0.8"/>
  </keyframe>
</mujoco>