<mujoco model="Robot">
  <default>
    <default class="robot">
      <default class="motor">
        <joint/>
        <motor ctrlrange="-23.7 23.7"/>
      </default>
      <default class="visual">
        <geom material="visualgeom" contype="0" conaffinity="0" group="2" />
      </default>
      <default class="collision">
        <geom material="collision_material" condim="3" contype="0" conaffinity="1" priority="1" group="1" solref="0.005 1" friction="1 0.01 0.01" />
        <equality solimp="0.99 0.999 1e-05" solref="0.005 1" />
      </default>
    </default>
  </default>



  <compiler angle="radian" />

  <asset>
    <material name="default_material" rgba="0.7 0.7 0.7 1" />
    <material name="collision_material" rgba="1.0 0.28 0.1 0.9" />
    <mesh name="luna_urdf_ros_battery_mockup001_zgrxpo.stl" file="/home/jonas/kamaro/luna_ws/src/cad/meshes/luna_urdf_ros_battery_mockup001_zgrxpo.stl" />
    <mesh name="luna_urdf_ros_msi_cubi_n_adl_8ckfc7.stl" file="/home/jonas/kamaro/luna_ws/src/cad/meshes/luna_urdf_ros_msi_cubi_n_adl_8ckfc7.stl" />
    <mesh name="luna_urdf_ros_main_body_floor_uiflal.stl" file="/home/jonas/kamaro/luna_ws/src/cad/meshes/luna_urdf_ros_main_body_floor_uiflal.stl" />
    <mesh name="luna_urdf_ros_main_body_floor_bracket_y25awi.stl" file="/home/jonas/kamaro/luna_ws/src/cad/meshes/luna_urdf_ros_main_body_floor_bracket_y25awi.stl" />
    <mesh name="luna_urdf_ros_main_body_floor_bracket001_gxy38g.stl" file="/home/jonas/kamaro/luna_ws/src/cad/meshes/luna_urdf_ros_main_body_floor_bracket001_gxy38g.stl" />
    <mesh name="luna_urdf_ros_main_body_floor_bracket002_glrktg.stl" file="/home/jonas/kamaro/luna_ws/src/cad/meshes/luna_urdf_ros_main_body_floor_bracket002_glrktg.stl" />
    <mesh name="luna_urdf_ros_main_body_floor_bracket003_xtkoak.stl" file="/home/jonas/kamaro/luna_ws/src/cad/meshes/luna_urdf_ros_main_body_floor_bracket003_xtkoak.stl" />
    <mesh name="luna_urdf_ros_luna_main_body_bracing_front_hap2rj.stl" file="/home/jonas/kamaro/luna_ws/src/cad/meshes/luna_urdf_ros_luna_main_body_bracing_front_hap2rj.stl" />
    <mesh name="luna_urdf_ros_luna_main_body_bracing_front_m_krv1i8.stl" file="/home/jonas/kamaro/luna_ws/src/cad/meshes/luna_urdf_ros_luna_main_body_bracing_front_m_krv1i8.stl" />
    <mesh name="luna_urdf_ros_carbon_rod_short_front_ap3ldc.stl" file="/home/jonas/kamaro/luna_ws/src/cad/meshes/luna_urdf_ros_carbon_rod_short_front_ap3ldc.stl" />
    <mesh name="luna_urdf_ros_carbon_rod_short_front001_yilhei.stl" file="/home/jonas/kamaro/luna_ws/src/cad/meshes/luna_urdf_ros_carbon_rod_short_front001_yilhei.stl" />
    <mesh name="luna_urdf_ros_luna_main_body_front_leg_spacer_8k444y.stl" file="/home/jonas/kamaro/luna_ws/src/cad/meshes/luna_urdf_ros_luna_main_body_front_leg_spacer_8k444y.stl" />
    <mesh name="luna_urdf_ros_main_body_front_leg_spacer_m_3cd2r5.stl" file="/home/jonas/kamaro/luna_ws/src/cad/meshes/luna_urdf_ros_main_body_front_leg_spacer_m_3cd2r5.stl" />
    <mesh name="luna_urdf_ros_battery_carrier_t3zanc.stl" file="/home/jonas/kamaro/luna_ws/src/cad/meshes/luna_urdf_ros_battery_carrier_t3zanc.stl" />
    <mesh name="luna_urdf_ros_battery_carrier001_2viesq.stl" file="/home/jonas/kamaro/luna_ws/src/cad/meshes/luna_urdf_ros_battery_carrier001_2viesq.stl" />
    <mesh name="luna_urdf_ros_carbon_rod_short_back_sg6ntt.stl" file="/home/jonas/kamaro/luna_ws/src/cad/meshes/luna_urdf_ros_carbon_rod_short_back_sg6ntt.stl" />
    <mesh name="luna_urdf_ros_carbon_rod_med_mid_48v6o8.stl" file="/home/jonas/kamaro/luna_ws/src/cad/meshes/luna_urdf_ros_carbon_rod_med_mid_48v6o8.stl" />
    <mesh name="luna_urdf_ros_carbon_rod_med_mid001_xpjqbv.stl" file="/home/jonas/kamaro/luna_ws/src/cad/meshes/luna_urdf_ros_carbon_rod_med_mid001_xpjqbv.stl" />
    <mesh name="luna_urdf_ros_battery_carrier003_ox00ax.stl" file="/home/jonas/kamaro/luna_ws/src/cad/meshes/luna_urdf_ros_battery_carrier003_ox00ax.stl" />
    <mesh name="luna_urdf_ros_battery_carrier004_gichag.stl" file="/home/jonas/kamaro/luna_ws/src/cad/meshes/luna_urdf_ros_battery_carrier004_gichag.stl" />
    <mesh name="luna_urdf_ros_luna_main_body_bracing_rear_wlvocg.stl" file="/home/jonas/kamaro/luna_ws/src/cad/meshes/luna_urdf_ros_luna_main_body_bracing_rear_wlvocg.stl" />
    <mesh name="luna_urdf_ros_luna_main_body_bracing_back_m_5ersgj.stl" file="/home/jonas/kamaro/luna_ws/src/cad/meshes/luna_urdf_ros_luna_main_body_bracing_back_m_5ersgj.stl" />
    <mesh name="luna_urdf_ros_carbon_rod_short_back001_uhh4jw.stl" file="/home/jonas/kamaro/luna_ws/src/cad/meshes/luna_urdf_ros_carbon_rod_short_back001_uhh4jw.stl" />
    <mesh name="luna_urdf_ros_carbon_rod_short_back002_qawnfn.stl" file="/home/jonas/kamaro/luna_ws/src/cad/meshes/luna_urdf_ros_carbon_rod_short_back002_qawnfn.stl" />
    <mesh name="luna_urdf_ros_m5_washer_cadgj0.stl" file="/home/jonas/kamaro/luna_ws/src/cad/meshes/luna_urdf_ros_m5_washer_cadgj0.stl" />
    <mesh name="luna_urdf_ros_m5_washer001_9gdu8k.stl" file="/home/jonas/kamaro/luna_ws/src/cad/meshes/luna_urdf_ros_m5_washer001_9gdu8k.stl" />
    <mesh name="luna_urdf_ros_carbon_rod_short_front002_csar1d.stl" file="/home/jonas/kamaro/luna_ws/src/cad/meshes/luna_urdf_ros_carbon_rod_short_front002_csar1d.stl" />
    <mesh name="luna_urdf_ros_shoulder_bracket_v92fcl.stl" file="/home/jonas/kamaro/luna_ws/src/cad/meshes/luna_urdf_ros_shoulder_bracket_v92fcl.stl" />
    <mesh name="luna_urdf_ros_shoulder_bracket001_krsxbd.stl" file="/home/jonas/kamaro/luna_ws/src/cad/meshes/luna_urdf_ros_shoulder_bracket001_krsxbd.stl" />
    <mesh name="luna_urdf_ros_shoulder_bracket003_0wl8pl.stl" file="/home/jonas/kamaro/luna_ws/src/cad/meshes/luna_urdf_ros_shoulder_bracket003_0wl8pl.stl" />
    <mesh name="luna_urdf_ros_shoulder_bracket004_tbj1ke.stl" file="/home/jonas/kamaro/luna_ws/src/cad/meshes/luna_urdf_ros_shoulder_bracket004_tbj1ke.stl" />
    <mesh name="luna_urdf_ros_shoulder_bracket_front_zkfwtd.stl" file="/home/jonas/kamaro/luna_ws/src/cad/meshes/luna_urdf_ros_shoulder_bracket_front_zkfwtd.stl" />
    <mesh name="luna_urdf_ros_shoulder_bracket_front001_ghdiay.stl" file="/home/jonas/kamaro/luna_ws/src/cad/meshes/luna_urdf_ros_shoulder_bracket_front001_ghdiay.stl" />
    <mesh name="luna_urdf_ros_shoulder_bracket_rear_gngufl.stl" file="/home/jonas/kamaro/luna_ws/src/cad/meshes/luna_urdf_ros_shoulder_bracket_rear_gngufl.stl" />
    <mesh name="luna_urdf_ros_shoulder_bracket_rear001_2blird.stl" file="/home/jonas/kamaro/luna_ws/src/cad/meshes/luna_urdf_ros_shoulder_bracket_rear001_2blird.stl" />
    <mesh name="luna_urdf_ros_main_body_leg_rail_peda3f.stl" file="/home/jonas/kamaro/luna_ws/src/cad/meshes/luna_urdf_ros_main_body_leg_rail_peda3f.stl" />
    <mesh name="luna_urdf_ros_main_body_leg_rail_mirror_3wdfih.stl" file="/home/jonas/kamaro/luna_ws/src/cad/meshes/luna_urdf_ros_main_body_leg_rail_mirror_3wdfih.stl" />
    <mesh name="luna_urdf_ros_battery_mockup_xgvtf3.stl" file="/home/jonas/kamaro/luna_ws/src/cad/meshes/luna_urdf_ros_battery_mockup_xgvtf3.stl" />
    <mesh name="unnamed_schulter_luna004_w9mdzc.stl" file="/home/jonas/kamaro/luna_ws/src/cad/meshes/unnamed_schulter_luna004_w9mdzc.stl" />
    <mesh name="unnamed_cybergearmotor_sw003_tzzudj.stl" file="/home/jonas/kamaro/luna_ws/src/cad/meshes/unnamed_cybergearmotor_sw003_tzzudj.stl" />
    <mesh name="unnamed_solid_y4u6ue.stl" file="/home/jonas/kamaro/luna_ws/src/cad/meshes/unnamed_solid_y4u6ue.stl" />
    <mesh name="unnamed_shell_rfigsq.stl" file="/home/jonas/kamaro/luna_ws/src/cad/meshes/unnamed_shell_rfigsq.stl" />
    <mesh name="unnamed_cybergearmotor_sw004_x135va.stl" file="/home/jonas/kamaro/luna_ws/src/cad/meshes/unnamed_cybergearmotor_sw004_x135va.stl" />
    <mesh name="unnamed_oberschenkel_deckel_rme7b3.stl" file="/home/jonas/kamaro/luna_ws/src/cad/meshes/unnamed_oberschenkel_deckel_rme7b3.stl" />
    <mesh name="luna_leg_placeholder.stl" file="/home/jonas/kamaro/luna_ws/src/cad/meshes/luna_leg_placeholder.stl" />
    <mesh name="unnamed_cybergearmotor_sw004_soo9zr.stl" file="/home/jonas/kamaro/luna_ws/src/cad/meshes/unnamed_cybergearmotor_sw004_soo9zr.stl" />
  </asset>

  <worldbody>


    <body name="base_link" pos="0.00000000 0.00000000 0.38162502" quat="1 0 0 0" childclass="robot">
      <freejoint name="floating_base" />
      <body name="main_body" pos="0.0 0.0 0.0" quat="0.7071067811140325 0.7071067812590626 0.0 0.0">
        <body name="l_BATTERY_MOCKUP003" pos="0.0 0.0 0.0" quat="1.0 0.0 0.0 0.0">
          <inertial pos="0.1 -0.0275 -0.08" quat="1.0 0.0 0.0 0.0" mass="0.8" diaginertia="0.001909583722 0.001874418605 0.000368406977" />
          <geom name="l_BATTERY_MOCKUP003_visual" pos="0.0 0.0 0.0" quat="1.0 0.0 0.0 0.0" material="default_material" type="mesh" mesh="luna_urdf_ros_battery_mockup001_zgrxpo.stl" class="visual" />
        </body>
        <body name="l_MSI_CUBI_N_ADL001" pos="0.0 0.0 0.0" quat="1.0 0.0 0.0 0.0">
          <inertial pos="-6.87573e-05 0.0267476 0.0619312" quat="1.0 0.0 0.0 0.0" mass="0.8674551936974197" diaginertia="0.0013112010012237612 0.002211379348017998 0.0013112010007840858" />
          <geom name="l_MSI_CUBI_N_ADL001_visual" pos="0.0 0.0 0.0" quat="1.0 0.0 0.0 0.0" material="default_material" type="mesh" mesh="luna_urdf_ros_msi_cubi_n_adl_8ckfc7.stl" class="visual" />
        </body>
        <body name="l_LUNA_MAIN_BODY_ASM" pos="0.0 0.0 0.0" quat="1.0 0.0 0.0 0.0">
          <inertial pos="1.77319e-05 0.00215574 0.0763117" quat="1.0 0.0 0.0 0.0" mass="1.0214630086977319" diaginertia="0.0479553952442776 0.0523691518925125 0.0066283606672571" />
          <geom name="l_LUNA_MAIN_BODY_ASM_visual_0" pos="0.0 0.0 0.0" quat="1.0 0.0 0.0 0.0" material="default_material" type="mesh" mesh="luna_urdf_ros_main_body_floor_uiflal.stl" class="visual" />
          <geom name="l_LUNA_MAIN_BODY_ASM_visual_1" pos="0.0 0.0 0.0" quat="1.0 0.0 0.0 0.0" material="default_material" type="mesh" mesh="luna_urdf_ros_main_body_floor_bracket_y25awi.stl" class="visual" />
          <geom name="l_LUNA_MAIN_BODY_ASM_visual_2" pos="0.0 0.0 0.0" quat="1.0 0.0 0.0 0.0" material="default_material" type="mesh" mesh="luna_urdf_ros_main_body_floor_bracket001_gxy38g.stl" class="visual" />
          <geom name="l_LUNA_MAIN_BODY_ASM_visual_3" pos="0.0 0.0 0.0" quat="1.0 0.0 0.0 0.0" material="default_material" type="mesh" mesh="luna_urdf_ros_main_body_floor_bracket002_glrktg.stl" class="visual" />
          <geom name="l_LUNA_MAIN_BODY_ASM_visual_4" pos="0.0 0.0 0.0" quat="1.0 0.0 0.0 0.0" material="default_material" type="mesh" mesh="luna_urdf_ros_main_body_floor_bracket003_xtkoak.stl" class="visual" />
          <geom name="l_LUNA_MAIN_BODY_ASM_visual_5" pos="0.0 0.0 0.0" quat="1.0 0.0 0.0 0.0" material="default_material" type="mesh" mesh="luna_urdf_ros_luna_main_body_bracing_front_hap2rj.stl" class="visual" />
          <geom name="l_LUNA_MAIN_BODY_ASM_visual_6" pos="0.0 0.0 0.0" quat="1.0 0.0 0.0 0.0" material="default_material" type="mesh" mesh="luna_urdf_ros_luna_main_body_bracing_front_m_krv1i8.stl" class="visual" />
          <geom name="l_LUNA_MAIN_BODY_ASM_visual_7" pos="0.0 0.0 0.0" quat="1.0 0.0 0.0 0.0" material="default_material" type="mesh" mesh="luna_urdf_ros_carbon_rod_short_front_ap3ldc.stl" class="visual" />
          <geom name="l_LUNA_MAIN_BODY_ASM_visual_8" pos="0.0 0.0 0.0" quat="1.0 0.0 0.0 0.0" material="default_material" type="mesh" mesh="luna_urdf_ros_carbon_rod_short_front001_yilhei.stl" class="visual" />
          <geom name="l_LUNA_MAIN_BODY_ASM_visual_9" pos="0.0 0.0 0.0" quat="1.0 0.0 0.0 0.0" material="default_material" type="mesh" mesh="luna_urdf_ros_luna_main_body_front_leg_spacer_8k444y.stl" class="visual" />
          <geom name="l_LUNA_MAIN_BODY_ASM_visual_10" pos="0.0 0.0 0.0" quat="1.0 0.0 0.0 0.0" material="default_material" type="mesh" mesh="luna_urdf_ros_main_body_front_leg_spacer_m_3cd2r5.stl" class="visual" />
          <geom name="l_LUNA_MAIN_BODY_ASM_visual_11" pos="0.0 0.0 0.0" quat="1.0 0.0 0.0 0.0" material="default_material" type="mesh" mesh="luna_urdf_ros_battery_carrier_t3zanc.stl" class="visual" />
          <geom name="l_LUNA_MAIN_BODY_ASM_visual_12" pos="0.0 0.0 0.0" quat="1.0 0.0 0.0 0.0" material="default_material" type="mesh" mesh="luna_urdf_ros_battery_carrier001_2viesq.stl" class="visual" />
          <geom name="l_LUNA_MAIN_BODY_ASM_visual_13" pos="0.0 0.0 0.0" quat="1.0 0.0 0.0 0.0" material="default_material" type="mesh" mesh="luna_urdf_ros_carbon_rod_short_back_sg6ntt.stl" class="visual" />
          <geom name="l_LUNA_MAIN_BODY_ASM_visual_14" pos="0.0 0.0 0.0" quat="1.0 0.0 0.0 0.0" material="default_material" type="mesh" mesh="luna_urdf_ros_carbon_rod_med_mid_48v6o8.stl" class="visual" />
          <geom name="l_LUNA_MAIN_BODY_ASM_visual_15" pos="0.0 0.0 0.0" quat="1.0 0.0 0.0 0.0" material="default_material" type="mesh" mesh="luna_urdf_ros_carbon_rod_med_mid001_xpjqbv.stl" class="visual" />
          <geom name="l_LUNA_MAIN_BODY_ASM_visual_16" pos="0.0 0.0 0.0" quat="1.0 0.0 0.0 0.0" material="default_material" type="mesh" mesh="luna_urdf_ros_battery_carrier003_ox00ax.stl" class="visual" />
          <geom name="l_LUNA_MAIN_BODY_ASM_visual_17" pos="0.0 0.0 0.0" quat="1.0 0.0 0.0 0.0" material="default_material" type="mesh" mesh="luna_urdf_ros_battery_carrier004_gichag.stl" class="visual" />
          <geom name="l_LUNA_MAIN_BODY_ASM_visual_18" pos="0.0 0.0 0.0" quat="1.0 0.0 0.0 0.0" material="default_material" type="mesh" mesh="luna_urdf_ros_luna_main_body_bracing_rear_wlvocg.stl" class="visual" />
          <geom name="l_LUNA_MAIN_BODY_ASM_visual_19" pos="0.0 0.0 0.0" quat="1.0 0.0 0.0 0.0" material="default_material" type="mesh" mesh="luna_urdf_ros_luna_main_body_bracing_back_m_5ersgj.stl" class="visual" />
          <geom name="l_LUNA_MAIN_BODY_ASM_visual_20" pos="0.0 0.0 0.0" quat="1.0 0.0 0.0 0.0" material="default_material" type="mesh" mesh="luna_urdf_ros_carbon_rod_short_back001_uhh4jw.stl" class="visual" />
          <geom name="l_LUNA_MAIN_BODY_ASM_visual_21" pos="0.0 0.0 0.0" quat="1.0 0.0 0.0 0.0" material="default_material" type="mesh" mesh="luna_urdf_ros_carbon_rod_short_back002_qawnfn.stl" class="visual" />
          <geom name="l_LUNA_MAIN_BODY_ASM_visual_22" pos="0.0 0.0 0.0" quat="1.0 0.0 0.0 0.0" material="default_material" type="mesh" mesh="luna_urdf_ros_m5_washer_cadgj0.stl" class="visual" />
          <geom name="l_LUNA_MAIN_BODY_ASM_visual_23" pos="0.0 0.0 0.0" quat="1.0 0.0 0.0 0.0" material="default_material" type="mesh" mesh="luna_urdf_ros_m5_washer001_9gdu8k.stl" class="visual" />
          <geom name="l_LUNA_MAIN_BODY_ASM_visual_24" pos="0.0 0.0 0.0" quat="1.0 0.0 0.0 0.0" material="default_material" type="mesh" mesh="luna_urdf_ros_carbon_rod_short_front002_csar1d.stl" class="visual" />
        </body>
        <body name="l_Aluminium_Parts_Mainbody" pos="0.0 0.0 0.0" quat="1.0 0.0 0.0 0.0">
          <inertial pos="0.0 0.00936585 -0.0350625" quat="1.0 0.0 0.0 0.0" mass="1.651012936644721" diaginertia="0.08214524528555907 0.09145106282175246 0.01355393475040258" />
          <geom name="l_Aluminium_Parts_Mainbody_visual_0" pos="0.0 0.0 0.0" quat="1.0 0.0 0.0 0.0" material="default_material" type="mesh" mesh="luna_urdf_ros_shoulder_bracket_v92fcl.stl" class="visual" />
          <geom name="l_Aluminium_Parts_Mainbody_visual_1" pos="0.0 0.0 0.0" quat="1.0 0.0 0.0 0.0" material="default_material" type="mesh" mesh="luna_urdf_ros_shoulder_bracket001_krsxbd.stl" class="visual" />
          <geom name="l_Aluminium_Parts_Mainbody_visual_2" pos="0.0 0.0 0.0" quat="1.0 0.0 0.0 0.0" material="default_material" type="mesh" mesh="luna_urdf_ros_shoulder_bracket003_0wl8pl.stl" class="visual" />
          <geom name="l_Aluminium_Parts_Mainbody_visual_3" pos="0.0 0.0 0.0" quat="1.0 0.0 0.0 0.0" material="default_material" type="mesh" mesh="luna_urdf_ros_shoulder_bracket004_tbj1ke.stl" class="visual" />
          <geom name="l_Aluminium_Parts_Mainbody_visual_4" pos="0.0 0.0 0.0" quat="1.0 0.0 0.0 0.0" material="default_material" type="mesh" mesh="luna_urdf_ros_shoulder_bracket_front_zkfwtd.stl" class="visual" />
          <geom name="l_Aluminium_Parts_Mainbody_visual_5" pos="0.0 0.0 0.0" quat="1.0 0.0 0.0 0.0" material="default_material" type="mesh" mesh="luna_urdf_ros_shoulder_bracket_front001_ghdiay.stl" class="visual" />
          <geom name="l_Aluminium_Parts_Mainbody_visual_6" pos="0.0 0.0 0.0" quat="1.0 0.0 0.0 0.0" material="default_material" type="mesh" mesh="luna_urdf_ros_shoulder_bracket_rear_gngufl.stl" class="visual" />
          <geom name="l_Aluminium_Parts_Mainbody_visual_7" pos="0.0 0.0 0.0" quat="1.0 0.0 0.0 0.0" material="default_material" type="mesh" mesh="luna_urdf_ros_shoulder_bracket_rear001_2blird.stl" class="visual" />
          <geom name="l_Aluminium_Parts_Mainbody_visual_8" pos="0.0 0.0 0.0" quat="1.0 0.0 0.0 0.0" material="default_material" type="mesh" mesh="luna_urdf_ros_main_body_leg_rail_peda3f.stl" class="visual" />
          <geom name="l_Aluminium_Parts_Mainbody_visual_9" pos="0.0 0.0 0.0" quat="1.0 0.0 0.0 0.0" material="default_material" type="mesh" mesh="luna_urdf_ros_main_body_leg_rail_mirror_3wdfih.stl" class="visual" />
        </body>
        <body name="l_BATTERY_MOCKUP002" pos="0.0 0.0 0.0" quat="1.0 0.0 0.0 0.0">
          <inertial pos="-0.1 -0.0275 -0.08" quat="1.0 0.0 0.0 0.0" mass="0.8" diaginertia="0.001909583722 0.001874418605 0.000368406977" />
          <geom name="l_BATTERY_MOCKUP002_visual" pos="0.0 0.0 0.0" quat="1.0 0.0 0.0 0.0" material="default_material" type="mesh" mesh="luna_urdf_ros_battery_mockup_xgvtf3.stl" class="visual" />
        </body>
      </body>
      <body name="FL_shoulder_to_base" pos="0.142 -0.17 0.018" quat="0.7071067811140325 0.7071067812590626 0.0 0.0">
        <body name="FL_shoulder" pos="0 0 0" quat="1.0 0.0 0.0 0.0">
          <joint name="FL_shoulder_joint" type="hinge" ref="0.0" class="motor" range="-3.141592653589793 3.141592653589793" axis="0 0 -1" />
          <inertial pos="0.0239541 1.32614e-05 0.0573496" quat="0.5000000000000001 -0.5 -0.5 -0.4999999999999999" mass="0.29606928064225085" diaginertia="0.00020649930783863573 0.000423514416921427 0.000361865637965086" />
          <geom name="FL_l_LUNA_SHOULDER_JOINT_ASM001_visual_0" pos="0.039 0.0 0.05743" quat="0.5000000000000001 -0.5 -0.5 -0.4999999999999999" material="default_material" type="mesh" mesh="unnamed_schulter_luna004_w9mdzc.stl" size="1 1 -1" class="visual" />         <body name="FL_l_LUNA_UPPER_LEG_ASM" pos="0.04 0.0 0.05" quat="0.4999999999487241 -0.5000000000512759 0.5000000000512759 0.49999999994872407">
            <joint name="FL_upper_leg_joint" type="hinge" ref="0.0" class="motor" range="-3.141592653589793 3.141592653589793" axis="0 1 0" />
            <inertial pos="-0.0112269 -0.0324326 -0.072418" quat="0.7071067811865477 0.0 -0.7071067811865474 0.0" mass="0.22744829778611395" diaginertia="8.427858181667436e-05 0.00047287925978284676 0.0004518159194452576" />
            <geom name="FL_l_LUNA_UPPER_LEG_ASM_collision" pos="-0.000736336 -0.0309636 -0.07227" quat="0.7071067811865477 0.0 -0.7071067811865474 0.0" type="box" size="0.12766 0.0280000000000045 0.05039" class="collision" />
            <geom name="FL_l_LUNA_UPPER_LEG_ASM_visual_0" pos="-0.000126336 3.63695e-05 0.003" quat="0.7071067811865477 0.0 -0.7071067811865474 0.0" material="default_material" type="mesh" mesh="unnamed_solid_y4u6ue.stl" size="1 1 -1" class="visual" />
            <geom name="FL_l_LUNA_UPPER_LEG_ASM_visual_1" pos="-0.000126336 3.63695e-05 0.003" quat="0.7071067811865477 0.0 -0.7071067811865474 0.0" material="default_material" type="mesh" mesh="unnamed_shell_rfigsq.stl" size="1 1 -1" class="visual" />
            <geom name="FL_l_LUNA_UPPER_LEG_ASM_visual_2" pos="-0.000126336 3.63695e-05 0.003" quat="0.7071067811865477 0.0 -0.7071067811865474 0.0" material="default_material" type="mesh" mesh="unnamed_cybergearmotor_sw004_x135va.stl" size="1 1 -1" class="visual" />
            <geom name="FL_l_LUNA_UPPER_LEG_ASM_visual_3" pos="-0.000126336 3.63695e-05 0.003" quat="0.7071067811865477 0.0 -0.7071067811865474 0.0" material="default_material" type="mesh" mesh="unnamed_oberschenkel_deckel_rme7b3.stl" size="1 1 -1" class="visual" />
            <body name="FL_lower_leg" pos="0.02 0.0 -0.2" quat="-1.4503002513292787e-10 0.7071067811140325 0.7071067812590626 -1.4503002516267403e-10">
              <joint name="FL_lower_leg_joint" type="hinge" ref="0.0" class="motor" range="-3.141592653589793 3.141592653589793" axis="-1 0 0 " />
              <inertial pos="0.005 0.0 -0.0781594" quat="1.0 0.0 0.0 0.0" mass="0.0801992588761483" diaginertia="0.0002987842676361 0.0002927989540089 7.3219691818e-06" />
              <geom name="FL_lower_leg_collision" pos="0.005 0.0 0.1199659" quat="1.0 0.0 0.0 0.0" type="box" size="0.005 0.0199369631996926 0.0796591236912465" class="collision" />
              <geom name="FL_lower_leg_visual" pos="0.0 0.0 0.0" quat="1.0 0.0 0.0 0.0" material="default_material" type="mesh" mesh="luna_leg_placeholder.stl" size="1 1 -1" class="visual" />
            </body>
            <body name="FL_l_Cybergear_upper_leg" pos="0.0 0.0 0.0" quat="1.0 0.0 0.0 0.0">
              <inertial pos="0.000367633 -0.0720141 0.000118456" quat="1.0 0.0 0.0 0.0" mass="0.31390229078502988" diaginertia="4.560349035529633e-05 7.68401267724726e-05 4.68364298064408e-05" />
              <geom name="FL_l_Cybergear_upper_leg_visual" pos="0.0 0.0 0.0" quat="1.0 0.0 0.0 0.0" material="default_material" type="mesh" mesh="unnamed_cybergearmotor_sw004_soo9zr.stl" class="visual" />
            </body>
          </body>
        </body>
      </body>
      <body name="BL_shoulder_to_base" pos="0.115 0.35 0.018" quat="0.7071067811140325 0.7071067812590626 0.0 0.0">
        <body name="BL_shoulder" pos="0 0 0" quat="1.0 0.0 0.0 0.0">
          <joint name="BL_shoulder_joint" type="hinge" ref="0.0" class="motor" range="-3.141592653589793 3.141592653589793" axis="0 0 1" />
          <inertial pos="0.0239541 1.32614e-05 0.0573496" quat="0.5000000000000001 -0.5 -0.5 -0.4999999999999999" mass="0.29606928064225085" diaginertia="0.00020649930783863573 0.000423514416921427 0.000361865637965086" />
          <geom name="BL_l_LUNA_SHOULDER_JOINT_ASM001_visual_0" pos="0.039 0.0 0.05743" quat="0.5000000000000001 -0.5 -0.5 -0.4999999999999999" material="default_material" type="mesh" mesh="unnamed_schulter_luna004_w9mdzc.stl" size="-1 1 -1" class="visual" />
          <geom name="BL_l_LUNA_SHOULDER_JOINT_ASM001_visual_2" pos="0.039 0.0 0.05743" quat="0.5000000000000001 -0.5 -0.5 -0.4999999999999999" material="default_material" type="mesh" mesh="unnamed_cybergearmotor_sw003_tzzudj.stl" class="visual" />
          <body name="BL_l_LUNA_UPPER_LEG_ASM" pos="0.04 0.0 0.05" quat="0.4999999999487241 -0.5000000000512759 0.5000000000512759 0.49999999994872407">
            <joint name="BL_upper_leg_joint" type="hinge" ref="0.0" class="motor" range="-3.141592653589793 3.141592653589793" axis="0 1 0" />
            <inertial pos="-0.0112269 -0.0324326 -0.072418" quat="0.7071067811865477 0.0 -0.7071067811865474 0.0" mass="0.22744829778611395" diaginertia="8.427858181667436e-05 0.00047287925978284676 0.0004518159194452576" />
            <geom name="BL_l_LUNA_UPPER_LEG_ASM_collision" pos="-0.000736336 -0.0309636 -0.07227" quat="0.7071067811865477 0.0 -0.7071067811865474 0.0" type="box" size="0.12766 0.0280000000000045 0.05039" class="collision" />
            <geom name="BL_l_LUNA_UPPER_LEG_ASM_visual_0" pos="-0.000126336 3.63695e-05 0.003" quat="0.7071067811865477 0.0 -0.7071067811865474 0.0" material="default_material" type="mesh" mesh="unnamed_solid_y4u6ue.stl" size="1 1 -1" class="visual" />
            <geom name="BL_l_LUNA_UPPER_LEG_ASM_visual_1" pos="-0.000126336 3.63695e-05 0.003" quat="0.7071067811865477 0.0 -0.7071067811865474 0.0" material="default_material" type="mesh" mesh="unnamed_shell_rfigsq.stl" size="1 1 -1" class="visual" />
            <geom name="BL_l_LUNA_UPPER_LEG_ASM_visual_2" pos="-0.000126336 3.63695e-05 0.003" quat="0.7071067811865477 0.0 -0.7071067811865474 0.0" material="default_material" type="mesh" mesh="unnamed_cybergearmotor_sw004_x135va.stl" size="1 1 -1" class="visual" />
            <geom name="BL_l_LUNA_UPPER_LEG_ASM_visual_3" pos="-0.000126336 3.63695e-05 0.003" quat="0.7071067811865477 0.0 -0.7071067811865474 0.0" material="default_material" type="mesh" mesh="unnamed_oberschenkel_deckel_rme7b3.stl" size="1 1 -1" class="visual" />
            <body name="BL_lower_leg" pos="0.02 0.0 -0.2" quat="-1.4503002513292787e-10 0.7071067811140325 0.7071067812590626 -1.4503002516267403e-10">
              <joint name="BL_lower_leg_joint" type="hinge" ref="0.0" class="motor" range="-3.141592653589793 3.141592653589793" axis="-1 0 0 " />
              <inertial pos="0.005 0.0 -0.0781594" quat="1.0 0.0 0.0 0.0" mass="0.0801992588761483" diaginertia="0.0002987842676361 0.0002927989540089 7.3219691818e-06" />
              <geom name="BL_lower_leg_collision" pos="0.005 0.0 0.1199659" quat="1.0 0.0 0.0 0.0" type="box" size="0.005 0.0199369631996926 0.0796591236912465" class="collision" />
              <geom name="BL_lower_leg_visual" pos="0.0 0.0 0.0" quat="1.0 0.0 0.0 0.0" material="default_material" type="mesh" mesh="luna_leg_placeholder.stl" size="1 1 -1" class="visual" />
            </body>
            <body name="BL_l_Cybergear_upper_leg" pos="0.0 0.0 0.0" quat="1.0 0.0 0.0 0.0">
              <inertial pos="0.000367633 -0.0720141 0.000118456" quat="1.0 0.0 0.0 0.0" mass="0.31390229078502988" diaginertia="4.560349035529633e-05 7.68401267724726e-05 4.68364298064408e-05" />
              <geom name="BL_l_Cybergear_upper_leg_visual" pos="0.0 0.0 0.0" quat="1.0 0.0 0.0 0.0" material="default_material" type="mesh" mesh="unnamed_cybergearmotor_sw004_soo9zr.stl" class="visual" />
            </body>
          </body>
        </body>
      </body>
      <body name="FR_shoulder_to_base" pos="-0.142 -0.17 0.018" quat="0.7071067811140325 0.7071067812590626 0.0 0.0">
        <body name="FR_shoulder" pos="0 0 0" quat="-2.0510342851533115e-10 -0.0 0.0 1.0">
          <joint name="FR_shoulder_joint" type="hinge" ref="0.0" class="motor" range="-3.141592653589793 3.141592653589793" axis="0 0 -1" />
          <inertial pos="0.0239541 1.32614e-05 0.0573496" quat="0.5000000000000001 -0.5 -0.5 -0.4999999999999999" mass="0.29606928064225085" diaginertia="0.00020649930783863573 0.000423514416921427 0.000361865637965086" />
          <geom name="FR_l_LUNA_SHOULDER_JOINT_ASM001_visual_0" pos="0.039 0.0 0.05743" quat="0.5000000000000001 -0.5 -0.5 -0.4999999999999999" material="default_material" type="mesh" mesh="unnamed_schulter_luna004_w9mdzc.stl" size="1 1 -1" class="visual" />
          <geom name="FR_l_LUNA_SHOULDER_JOINT_ASM001_visual_2" pos="0.039 0.0 0.05743" quat="0.5000000000000001 -0.5 -0.5 -0.4999999999999999" material="default_material" type="mesh" mesh="unnamed_cybergearmotor_sw003_tzzudj.stl" class="visual" />
          <body name="FR_l_LUNA_UPPER_LEG_ASM" pos="0.04 0.0 0.05" quat="0.4999999999487241 0.5000000000512759 -0.5000000000512759 0.49999999994872407">
            <joint name="FR_upper_leg_joint" type="hinge" ref="0.0" class="motor" range="-3.141592653589793 3.141592653589793" axis="0 1 0" />
            <inertial pos="-0.0112269 -0.0324326 -0.072418" quat="0.7071067811865477 0.0 -0.7071067811865474 0.0" mass="0.22744829778611395" diaginertia="8.427858181667436e-05 0.00047287925978284676 0.0004518159194452576" />
            <geom name="FR_l_LUNA_UPPER_LEG_ASM_collision" pos="-0.000736336 -0.0309636 -0.07227" quat="0.7071067811865477 0.0 -0.7071067811865474 0.0" type="box" size="0.12766 0.0280000000000045 0.05039" class="collision" />
            <geom name="FR_l_LUNA_UPPER_LEG_ASM_visual_0" pos="-0.000126336 3.63695e-05 0.003" quat="0.7071067811865477 0.0 -0.7071067811865474 0.0" material="default_material" type="mesh" mesh="unnamed_solid_y4u6ue.stl" size="1 1 1" class="visual" />
            <geom name="FR_l_LUNA_UPPER_LEG_ASM_visual_1" pos="-0.000126336 3.63695e-05 0.003" quat="0.7071067811865477 0.0 -0.7071067811865474 0.0" material="default_material" type="mesh" mesh="unnamed_shell_rfigsq.stl" size="1 1 1" class="visual" />
            <geom name="FR_l_LUNA_UPPER_LEG_ASM_visual_2" pos="-0.000126336 3.63695e-05 0.003" quat="0.7071067811865477 0.0 -0.7071067811865474 0.0" material="default_material" type="mesh" mesh="unnamed_cybergearmotor_sw004_x135va.stl" size="1 1 1" class="visual" />
            <geom name="FR_l_LUNA_UPPER_LEG_ASM_visual_3" pos="-0.000126336 3.63695e-05 0.003" quat="0.7071067811865477 0.0 -0.7071067811865474 0.0" material="default_material" type="mesh" mesh="unnamed_oberschenkel_deckel_rme7b3.stl" size="1 1 1" class="visual" />
            <body name="FR_lower_leg" pos="-0.02 0.0 -0.2" quat="0.7071067811140325 0.0 0.0 0.7071067812590626">
              <joint name="FR_lower_leg_joint" type="hinge" ref="0.0" class="motor" range="-3.141592653589793 3.141592653589793" axis="-1 0 0 " />
              <inertial pos="0.005 0.0 -0.0781594" quat="1.0 0.0 0.0 0.0" mass="0.0801992588761483" diaginertia="0.0002987842676361 0.0002927989540089 7.3219691818e-06" />
              <geom name="FR_lower_leg_collision" pos="0.005 0.0 -0.1199659" quat="1.0 0.0 0.0 0.0" type="box" size="0.005 0.0199369631996926 0.0796591236912465" class="collision" />
              <geom name="FR_lower_leg_visual" pos="0.0 0.0 0.0" quat="1.0 0.0 0.0 0.0" material="default_material" type="mesh" mesh="luna_leg_placeholder.stl" size="1 1 1" class="visual" />
            </body>
            <body name="FR_l_Cybergear_upper_leg" pos="0.0 0.0 0.0" quat="1.0 0.0 0.0 0.0">
              <inertial pos="0.000367633 -0.0720141 0.000118456" quat="1.0 0.0 0.0 0.0" mass="0.31390229078502988" diaginertia="4.560349035529633e-05 7.68401267724726e-05 4.68364298064408e-05" />
              <geom name="FR_l_Cybergear_upper_leg_visual" pos="0.0 0.0 0.0" quat="1.0 0.0 0.0 0.0" material="default_material" type="mesh" mesh="unnamed_cybergearmotor_sw004_soo9zr.stl" class="visual" />
            </body>
          </body>
        </body>
      </body>
      <body name="BR_shoulder_to_base" pos="-0.115 0.35 0.018" quat="0.7071067811140325 0.7071067812590626 0.0 0.0">
        <body name="BR_shoulder" pos="0 0 0" quat="-2.0510342851533115e-10 -0.0 0.0 1.0">
          <joint name="BR_shoulder_joint" type="hinge" ref="0.0" class="motor" range="-3.141592653589793 3.141592653589793" axis="0 0 1" />
          <inertial pos="0.0239541 1.32614e-05 0.0573496" quat="0.5000000000000001 -0.5 -0.5 -0.4999999999999999" mass="0.29606928064225085" diaginertia="0.00020649930783863573 0.000423514416921427 0.000361865637965086" />
          <geom name="BR_l_LUNA_SHOULDER_JOINT_ASM001_visual_0" pos="0.039 0.0 0.05743" quat="0.5000000000000001 -0.5 -0.5 -0.4999999999999999" material="default_material" type="mesh" mesh="unnamed_schulter_luna004_w9mdzc.stl" size="-1 1 -1" class="visual" />
          <geom name="BR_l_LUNA_SHOULDER_JOINT_ASM001_visual_2" pos="0.039 0.0 0.05743" quat="0.5000000000000001 -0.5 -0.5 -0.4999999999999999" material="default_material" type="mesh" mesh="unnamed_cybergearmotor_sw003_tzzudj.stl" class="visual" />
          <body name="BR_l_LUNA_UPPER_LEG_ASM" pos="0.04 0.0 0.05" quat="0.4999999999487241 0.5000000000512759 -0.5000000000512759 0.49999999994872407">
            <joint name="BR_upper_leg_joint" type="hinge" ref="0.0" class="motor" range="-3.141592653589793 3.141592653589793" axis="0 1 0" />
            <inertial pos="-0.0112269 -0.0324326 -0.072418" quat="0.7071067811865477 0.0 -0.7071067811865474 0.0" mass="0.22744829778611395" diaginertia="8.427858181667436e-05 0.00047287925978284676 0.0004518159194452576" />
            <geom name="BR_l_LUNA_UPPER_LEG_ASM_collision" pos="-0.000736336 -0.0309636 -0.07227" quat="0.7071067811865477 0.0 -0.7071067811865474 0.0" type="box" size="0.12766 0.0280000000000045 0.05039" class="collision" />
            <geom name="BR_l_LUNA_UPPER_LEG_ASM_visual_0" pos="-0.000126336 3.63695e-05 0.003" quat="0.7071067811865477 0.0 -0.7071067811865474 0.0" material="default_material" type="mesh" mesh="unnamed_solid_y4u6ue.stl" size="1 1 1" class="visual" />
            <geom name="BR_l_LUNA_UPPER_LEG_ASM_visual_1" pos="-0.000126336 3.63695e-05 0.003" quat="0.7071067811865477 0.0 -0.7071067811865474 0.0" material="default_material" type="mesh" mesh="unnamed_shell_rfigsq.stl" size="1 1 1" class="visual" />
            <geom name="BR_l_LUNA_UPPER_LEG_ASM_visual_2" pos="-0.000126336 3.63695e-05 0.003" quat="0.7071067811865477 0.0 -0.7071067811865474 0.0" material="default_material" type="mesh" mesh="unnamed_cybergearmotor_sw004_x135va.stl" size="1 1 1" class="visual" />
            <geom name="BR_l_LUNA_UPPER_LEG_ASM_visual_3" pos="-0.000126336 3.63695e-05 0.003" quat="0.7071067811865477 0.0 -0.7071067811865474 0.0" material="default_material" type="mesh" mesh="unnamed_oberschenkel_deckel_rme7b3.stl" size="1 1 1" class="visual" />
            <body name="BR_lower_leg" pos="-0.02 0.0 -0.2" quat="0.7071067811140325 0.0 0.0 0.7071067812590626">
              <joint name="BR_lower_leg_joint" type="hinge" ref="0.0" class="motor" range="-3.141592653589793 3.141592653589793" axis="-1 0 0 " />
              <inertial pos="0.005 0.0 -0.0781594" quat="1.0 0.0 0.0 0.0" mass="0.0801992588761483" diaginertia="0.0002987842676361 0.0002927989540089 7.3219691818e-06" />
              <geom name="BR_lower_leg_collision" pos="0.005 0.0 -0.1199659" quat="1.0 0.0 0.0 0.0" type="box" size="0.005 0.0199369631996926 0.0796591236912465" class="collision" />
              <geom name="BR_lower_leg_visual" pos="0.0 0.0 0.0" quat="1.0 0.0 0.0 0.0" material="default_material" type="mesh" mesh="luna_leg_placeholder.stl" size="1 1 1" class="visual" />
            </body>
            <body name="BR_l_Cybergear_upper_leg" pos="0.0 0.0 0.0" quat="1.0 0.0 0.0 0.0">
              <inertial pos="0.000367633 -0.0720141 0.000118456" quat="1.0 0.0 0.0 0.0" mass="0.31390229078502988" diaginertia="4.560349035529633e-05 7.68401267724726e-05 4.68364298064408e-05" />
              <geom name="BR_l_Cybergear_upper_leg_visual" pos="0.0 0.0 0.0" quat="1.0 0.0 0.0 0.0" material="default_material" type="mesh" mesh="unnamed_cybergearmotor_sw004_soo9zr.stl" class="visual" />
            </body>
          </body>
        </body>
      </body>
      <site name="base_link_site" pos="0 0 0" quat="1 0 0 0" />
      <camera name="front_camera" mode="track" fovy="90.0" quat="4.329780281177467e-17 4.329780281177466e-17 0.7071067811865475 0.7071067811865476" pos="0.0 2.0 0.5" />
      <camera name="side_camera" mode="track" fovy="90.0" quat="-0.5 -0.4999999999999999 0.5 0.5000000000000001" pos="-2.0 0.0 0.5" />
    </body>
  </worldbody>

  <actuator>
    <motor name="FL_shoulder_joint_ctrl" joint="FL_shoulder_joint" class="motor" />
    <motor name="FL_upper_leg_joint_ctrl" joint="FL_upper_leg_joint" class="motor" />
    <motor name="FL_lower_leg_joint_ctrl" joint="FL_lower_leg_joint" class="motor" />
    <motor name="BL_shoulder_joint_ctrl" joint="BL_shoulder_joint" class="motor" />
    <motor name="BL_upper_leg_joint_ctrl" joint="BL_upper_leg_joint" class="motor" />
    <motor name="BL_lower_leg_joint_ctrl" joint="BL_lower_leg_joint" class="motor" />
    <motor name="FR_shoulder_joint_ctrl" joint="FR_shoulder_joint" class="motor" />
    <motor name="FR_upper_leg_joint_ctrl" joint="FR_upper_leg_joint" class="motor" />
    <motor name="FR_lower_leg_joint_ctrl" joint="FR_lower_leg_joint" class="motor" />
    <motor name="BR_shoulder_joint_ctrl" joint="BR_shoulder_joint" class="motor" />
    <motor name="BR_upper_leg_joint_ctrl" joint="BR_upper_leg_joint" class="motor" />
    <motor name="BR_lower_leg_joint_ctrl" joint="BR_lower_leg_joint" class="motor" />
  </actuator>

  <contact>
    <exclude body1="FL_l_LUNA_UPPER_LEG_ASM" body2="FL_lower_leg" />
    <exclude body1="BL_l_LUNA_UPPER_LEG_ASM" body2="BL_lower_leg" />
    <exclude body1="FR_l_LUNA_UPPER_LEG_ASM" body2="FR_lower_leg" />
    <exclude body1="BR_l_LUNA_UPPER_LEG_ASM" body2="BR_lower_leg" />
  </contact>

  <sensor>
    <framepos name="base_link_site_pos" objtype="site" objname="base_link_site" />
    <framequat name="base_link_site_quat" objtype="site" objname="base_link_site" />
    <framelinvel name="base_link_site_linvel" objtype="site" objname="base_link_site" />
    <frameangvel name="base_link_site_angvel" objtype="site" objname="base_link_site" />
    <velocimeter name="base_link_site_vel" site="base_link_site" />
  </sensor>
</mujoco>